
No hay trampas aquí. Simplemente reemplaza `.catch` con `try...catch` dentro de `demoGithubUser` y agrega `async/await` donde sea necesario:

```js run
class HttpError extends Error {
  constructor(response) {
    super(`${response.status} for ${response.url}`);
    this.name = 'HttpError';
    this.response = response;
  }
}

async function loadJson(url) {
  let response = await fetch(url);
  if (response.status == 200) {
    return response.json();
  } else {
    throw new HttpError(response);
  }
}

// Pregunta por un nombre de usuario hasta que github devuelve un usuario válido
async function demoGithubUser() {

  let user;
  while(true) {
    let name = prompt("Ingrese un nombre:", "iliakan");

    try {
      user = await loadJson(`https://api.github.com/users/${name}`);
      break; // sin error, salir del bucle
    } catch(err) {
      if (err instanceof HttpError && err.response.status == 404) {
        // bucle continúa después del alert
        alert("No existe tal usuario, por favor reingrese.");
      } else {
        // error desconocido, lo relanza
        throw err;
      }
    }      
  }


  alert(`Nombre completo: ${user.name}.`);
  return user;
}

demoGithubUser();
```
